Workbook

Sheet Hoja1
A1: cod_lre | B1: concepto_detalle | C1: Tipo
A2: Viáticos(2303) | B2: viaticoMi | C2: Haber exento
A3: Tratos(2112) | B3: tratoMi | C3: Haber afecto
A4: Total líquido(5501) | B4: totalesEmpl | C4: Descuento
A5: Sueldo(2101) | B5: sueldoBase | C5: Haber afecto
A6: Sueldo empresarial (2161) | B6: sueldoBase | C6: Haber afecto
A7: Subsidio por incapacidad laboral por licencia médica(2201) | B7: otrosHaberes | C7: Haber afecto
A8: Sobresueldo(2102) | B8: sobresueldoMi | C8: Haber afecto
A9: Semana corrida(2104) | B9: semanaCorr | C9: Haber afecto
A10: Sala cuna(2308) | B10: salaCMi | C10: Haber exento
A11: Retención préstamo clase media 2020 (Ley 21.252) (3166) | B11: solidarioremu | C11: Descuento Legal
A12: Remuneraciones trimestrales(2117) | B12: otrosHaberes | C12: Haber afecto
... A94: AFC - Aporte empleador(4151) | B94: cesAporteCi | C94: Aporte Empleador

Sheet Hoja2
F1: Fecha de proceso | G1: Fecha de proceso
B2: Fecha de proceso | F2: Id empleado | G2: Id empleado
B3: Id empleado | F3: Número de contrato | G3: Número de contrato
B4: Número de contrato | F4: Id del concepto
B5: Id de empresa | F5: Monto del concepto
B6: afp | F6: Afecto
B7: %afp | F7: Id de institución | G7: afp | H7: isapre | I7: mutual | J7: Ccaf
B8: isapre | F8: Cotización de jubilación | G8: %afp | H8: % mutual | I8: %Sis | J8: % mutual | K8: 0.6 | L8: %ccaf
B9: Ccaf | F9: Días de licencias | G9: Nro días de licencia médica
B10: % Ccaf | F10: Días trabajados | G10: Nro días trabajados
B11: Mutual | F11: Fecha de aplicación
B12: % mutual | F12: Empresa | G12: Id de empresa
B13: %Sis | F13: Total de rebajas por LLSS
B14: Nro días trabajados | F14: Rentas no gravadas
B15: Nro días de licencia médica | C15: licenciaDias | F15: Rebaja por zona extrema
B16: Sueldo(2101) | C16: =VLOOKUP(B16,Hoja1!A:B,2,0) -> sueldoBase | F16: Jornada
B17: Sobresueldo(2102) | C17: =VLOOKUP(B17,Hoja1!A:B,2,0) -> sobresueldoMi | F17: Días de vacaciones
B18: Comisiones(2103) | C18: =VLOOKUP(B18,Hoja1!A:B,2,0) -> comisionMi | F18: Monto Init
B19: Semana corrida(2104) | C19: =VLOOKUP(B19,Hoja1!A:B,2,0) -> semanaCorr | F19: Fase
B20: Participación(2105) | C20: =VLOOKUP(B20,Hoja1!A:B,2,0) -> participacionMi
B21: Gratificación(2106) | C21: =VLOOKUP(B21,Hoja1!A:B,2,0) -> gratificacion
B22: Recargo 30% día domingo (Art. 38) (2107) | C22: recargoMi
B23: Remuneración variable pagada en vacaciones (Art 71) (cód 2108) | C23: remvarMi
B24: Aguinaldo(2110) | C24: =VLOOKUP(B24,Hoja1!A:B,2,0) -> AguinaldoMi
B25: Bonos u otras remun. fijas mensuales(2111) | C25: =VLOOKUP(B25,Hoja1!A:B,2,0) -> BonoMi
B26: Tratos (mensual) (cód 2112) | C26: tratoMi
B27: Bonos u otras remuneraciones variables mensuales o superiores a un mes (cód 2113) | C27: bonsupMi
B28: Beneficios en especie constitutivos de remuneración (cód 2115) | C28: benefMi
B29: Otras remuneraciones superiores a un mes (cód 2123) | C29: otremMi
B30: Pago por horas de trabajo sindical (cód 2124) | C30: pagosindMi
B31: Subsidio por incapacidad laboral por licencia médica(2201) | C31: =VLOOKUP(B31,Hoja1!A:B,2,0) -> otrosHaberes
B32: Beca de estudio (Art. 17 N°18 LIR) (cód 2202) | C32: otrosHaberes
B33: Otros ingresos no constitutivos de renta (Art 17 N°29 LIR) (cód 2204) | C33: otingrMi
B34: Colación(2301) | C34: =VLOOKUP(B34,Hoja1!A:B,2,0) -> colacion
B35: Movilización(2302) | C35: =VLOOKUP(B35,Hoja1!A:B,2,0) -> movilizacion
B36: Viáticos totales mensual (Art 41) (cód 2303) | C36: gastoMi
B37: Asignación de pérdida de caja(2304) | C37: =VLOOKUP(B37,Hoja1!A:B,2,0) -> asigPerdCajaMi
B38: Asignación de desgaste herramienta(2305) | C38: =VLOOKUP(B38,Hoja1!A:B,2,0) -> AsigDesgHerrMi
B39: Gastos por causa del trabajo (Art 41 CdT) y gastos de representación (Art. 42 Nº1 LIR) (cód 2306) | C39: salaCMi
B40: Sala cuna (Art 203) (cód 2308) | C40: salaCMi
...
